Workbook

Sheet README
A1: attribution_audit.xlsx
A2: Filer | B2: Berkshire Hathaway (BW-FILER-CIK0001067983)
A3: Generated | B3: 2026-09-07 · project closeout re-audit (supersedes the 2026-08-03 workbook)
A4: Why regenerated | B4: Two bugs invalidated the 2026-08-03 numbers: (1) NaN-day poisoning in window_return silently nulled quarters (n 35->42, lagged gross Sharpe 0.85->0.99); (2) the TERMINAL row of get_filer_portfolio carries an open-ended forward return, not a one-quarter one, and was inflating the Stage 0 gate. Both fixed; every figure below is from the current run.
A5: Purpose | B5: Recompute every published attribution number by hand. Summary sheet uses live formulas referencing Berkshire_quarterly.
A7: METHOD
A8: Returns | B8: GROSS returns, NOT excess over benchmark. Long-only 13F book. No costs/financing/borrow.
A9: Rebuild | B9: Daily name-level: holdings weights x get_returns_decomposition per-name additive layers (l1=market, l2=sector, l3=subsector, l3_residual=idio). Renormalised to covered names.
A10: Unlagged: TWO | B10: There are two unlagged twins and they answer different questions. UNLQ = teo -> teo+3 months, a fixed forward quarter; this matches the endpoint's own window, so use it to compare rebuild vs endpoint (Stage 0, Sharpe_bridge step C). UNLT = teo_i -> teo_j (next usable book), q_len-normalised; this mirrors the LAGGED window structure exactly, so use it for 'does the premium survive the lag'. They coincide except on the 6 windows spanning a missing book. An earlier workbook compared UNLQ against LAGGED, mixing the two — do not do that.
A11: Lagged window | B11: entry -> next entry, entry = teo + 45 CALENDAR days rolled to next trading day. Always invested; across a missing book the book is held longer (q_len>1).
A12: q_len | B12: window length in quarters. Per-quarter figures in the summary divide lagged window returns by q_len.
A14: CAVEATS
A15: Sample | B15: 42 quarters. 3 excluded as STUB ROWS (2014-09-30, 2020-09-30, 2025-03-31) — those portfolio rows describe a 1-2 name portfolio holding 0.001%-0.8% of the AUM the neighbouring quarters report, so no holdings book matches them. 1 excluded as the terminal row (2025-12-31). Only 2021-06-30 is genuinely absent from the teo series; 2013-06-30 / 2015-06-30 / 2023-09-30 / 2023-12-31 are present but carry no portfolio_gross_return.
A16: Rebuild bias | B16: Rebuild runs ~median +12 bps/q rich vs the endpoint's model-implied gross. Cancels in lagged-vs-unlagged deltas.
A17: Linking residual | B17: Layers compounded each as own stream; sum != gross exactly (residual column). Small, matches the endpoint's own construction.
A18: The 1.00 Sharpe | B18: Do NOT quote 1.003. It is computed over 46 quarters including three stub rows whose drop-idio returns average 837 bps/q against 372 for the real quarters. On the rebuildable sample the endpoint gives 0.91 and the independent daily rebuild 0.93. See Sharpe_bridge.
A19: Hit-rate correction | B19: Meeting note '65% hit in L1' is WRONG. L1/market hit is far higher unlagged; 65% was sector+subsector. See Hit_rate (recomputed this run).
A20: Filing dates | B20: '45-day lag' is 63-68% exactly 45 across four filers -> largely a report_date+45 placeholder, not observed. See Lag_distribution.
A21: SHEETS | B21: Berkshire_quarterly (raw data) · Berkshire_summary (live formulas) · Sharpe_bridge · Hit_rate · Lag_distribution

Sheet Berkshire_quarterly
A1: teo | B1: entry_date | C1: exit_date | D1: q_len | E1: n_names | F1: covered_weight | G1: gross_UNLQ | H1: market_UNLQ | I1: sector_UNLQ | J1: subsector_UNLQ | K1: idio_UNLQ | L1: linkresid_UNLQ | M1: gross_UNLT | N1: market_UNLT | O1: sector_UNLT | P1: subsector_UNLT | Q1: idio_UNLT | R1: gross_LAG | S1: market_LAG | T1: sector_LAG | U1: subsector_LAG | V1: idio_LAG | W1: linkresid_LAG | X1: gross_LAG_perQ | Y1: market_LAG_perQ | Z1: sector_LAG_perQ | AA1: subsector_LAG_perQ | AB1: idio_LAG_perQ
A2: 2013-09-30 | B2: 2013-11-14 | C2: 2014-02-14 | D2: 1.0075291 | E2: 18 | F2: 0.96750047 | G2: 0.096404911 | H2: 0.087224158 | I2: 0.0024778213 | J2: 0.0047613812 | K2: 0.0012968066 | L2: 0.00064474349 | M2: 0.10208269 | N2: 0.091028716 | O2: 0.0014647654 | P2: 0.0047771962 | Q2: 0.0039514176 | R2: 0.01144254 | S2: 0.028420659 | T2: -0.017077445 | U2: 0.0037931764 | V2: -0.0031091925 | W2: -0.00058465788 | X2: 0.011357032 | Y2: 0.028208276 | Z2: -0.016949828 | AA2: 0.0037648306 | AB2: -0.0030859581
A3: 2013-12-31 | B3: 2014-02-14 | C3: 2014-05-15 | D3: 0.98562628 | E3: 17 | F3: 0.96671959 | G3: -0.020552719 | H3: 0.016572276 | I3: -0.0019105673 | J3: -0.0016237207 | K3: -0.033325062 | L3: -0.00026564435 | M3: -0.020852446 | N3: 0.016813955 | O3: -0.0019384298 | P3: -0.0016474 | Q3: -0.033811053 | R3: 0.015330973 | S3: 0.020833426 | T3: 0.0092026696 | U3: -0.0083152305 | V3: -0.0062571668 | W3: -0.00013272569 | X3: 0.015554549 | Y3: 0.021137247 | Z3: 0.0093368752 | AA3: -0.0084364943 | AB3: -0.0063484171
A4: 2014-03-31 | B4: 2014-05-15 | C4: 2014-08-14 | D4: 0.99657769 | E4: 17 | F4: 0.96516433 | G4: 0.031511687 | H4: 0.045307264 | I4: -0.0044661809 | J4: -0.0051107865 | K4: -0.0043331649 | L4: 0.00011455517 | M4: 0.0316199 | N4: 0.045462852 | O4: -0.004481518 | P4: -0.0051283373 | Q4: -0.0043480452 | R4: 0.012339485 | S4: 0.044100459 | T4: -0.0050334755 | U4: 0.00027395063 | V4: -0.025452999 | W4: -0.0015484501 | X4: 0.01238186 | Y4: 0.044251903 | Z4: -0.0050507608 | AA4: 0.0002748914 | AB4: -0.025540406
A5: 2014-06-30 | B5: 2014-08-14 | C5: 2015-02-17 | D5: 2.0479124 | E5: 18 | F5: 0.96808746 | G5: 0.0093514241 | H5: 0.0092218993 | I5: 0.0082071066 | J5: -1.1215429e-05 | K5: -0.0071579084 | L5: -0.00090845802 | M5: 0.0070773512 | N5: 0.025708355 | O5: 0.014110772 | P5: -0.00018906086 | Q5: -0.030254518 | R5: -0.0044495443 | S5: 0.074602981 | T5: 0.023574596 | U5: 0.00045263471 | V5: -0.09609813 | W5: -0.0069816259 | X5: -0.002172722 | Y5: 0.036428795 | Z5: 0.011511526 | AA5: 0.0002210225 | AB5: -0.046924923
A6: 2014-12-31 | B6: 2015-02-17 | C6: 2015-05-15 | D6: 0.95277207 | E6: 19 | F6: 0.96415122 | G6: -0.045319013 | H6: 0.0085297014 | I6: -0.0044363532 | J6: 0.00069317895 | K6: -0.0507536 | L6: 0.00064806073 | M6: -0.047565429 | N6: 0.0089525099 | O6: -0.0046562586 | P6: 0.00072753911 | Q6: -0.053269404 | R6: 0.019714994 | S6: 0.014527567 | T6: -0.00089930667 | U6: 0.00099743732 | V6: 0.0051342106 | W6: -4.4914351e-05 | X6: 0.020692246 | Y6: 0.015247684 | Z6: -0.00094388437 | AA6: 0.0010468793 | AB6: 0.0053887081
A7: 2015-03-31 | B7: 2015-05-15 | C7: 2015-11-16 | D7: 2.0260096 | E7: 19 | F7: 0.95678909 | G7: -0.009137547 | H7: 0.0023451885 | I7: -0.0033839416 | J7: 0.0011842508 | K7: -0.0092907611 | L7: 7.716403e-06 | M7: -0.029753893 | N7: -0.026475381 | O7: 0.0084052354 | P7: -0.0012639791 | Q7: -0.011027912 | R7: -0.085854335 | S7: -0.022414466 | T7: 0.010025629 | U7: -0.0035388192 | V7: -0.071312149 | W7: 0.0013854714 | X7: -0.042376075 | Y7: -0.011063357 | Z7: 0.0049484606 | AA7: -0.0017466942 | AB7: -0.035198328
A8: 2015-09-30 | B8: 2015-11-16 | C8: 2016-02-16 | D8: 1.0075291 | E8: 19 | F8: 0.95713039 | G8: 0.033039295 | H8: 0.067133554 | I8: 0.0071754729 | J8: -0.0017021556 | K8: -0.03724555 | L8: -0.0023220262 | M8: 0.021698834 | N8: 0.057815752 | O8: 0.0059403301 | P8: -0.0015447563 | Q8: -0.03837016 | R8: -0.059766006 | S8: -0.059727595 | T8: 0.023473196 | U8: -0.0014133106 | V8: -0.025698331 | W8: 0.0036000347 | X8: -0.059319385 | Y8: -0.059281261 | Z8: 0.023297785 | AA8: -0.0014027492 | AB8: -0.025506292
A9: 2015-12-31 | B9: 2016-02-16 | C9: 2016-05-16 | D9: 0.98562628 | E9: 20 | F9: 0.95876391 | G9: 0.03198683 | H9: 0.0074510958 | I9: 0.0071900317 | J9: -0.0036817616 | K9: 0.018589247 | L9: 0.0024382173 | M9: 0.032453305 | N9: 0.0075597576 | O9: 0.0072948863 | P9: -0.0037354539 | Q9: 0.01886034 | R9: 0.12044205 | S9: 0.074550326 | T9: 9.3948703e-05 | U9: -0.0070178469 | V9: 0.050571844 | W9: 0.0022437784 | X9: 0.1221985 | Y9: 0.075637518 | Z9: 9.5318788e-05 | AA9: -0.0071201905 | AB9: 0.05130935
A10: 2016-03-31 | B10: 2016-05-16 | C10: 2016-08-15 | D10: 0.99657769 | E10: 21 | F10: 0.97075032 | G10: -0.0048614042 | H10: 0.020129431 | I10: 0.0029775049 | J10: -0.0074258097 | K10: -0.018503506 | L10: -0.0020390247 | M10: -0.0048780986 | N10: 0.020198557 | O10: 0.0029877299 | P10: -0.0074513104 | Q10: -0.018567048 | R10: 0.03652046 | S10: 0.053708004 | T10: -0.0038630159 | U10: 0.002482918 | V10: -0.01439302 | W10: -0.0014144259 | X10: 0.036645873 | Y10: 0.053892441 | Z10: -0.0038762817 | AA10: 0.0024914445 | AB10: -0.014442447
A11: 2016-06-30 | B11: 2016-08-15 | C11: 2016-11-14 | D11: 0.99657769 | E11: 22 | F11: 0.98389506 | G11: 0.030208374 | H11: 0.031794752 | I11: -0.0072563707 | J11: 0.0073058069 | K11: -0.0023564326 | L11: 0.00072061759 | M11: 0.030312111 | N11: 0.031903938 | O11: -0.0072812896 | P11: 0.0073308956 | Q11: -0.0023645247 | R11: 0.003715138 | S11: -0.004957856 | T11: 0.0046765078 | U11: -0.00061814842 | V11: 0.0045073346 | W11: 0.00010729999 | X11: 0.003727896 | Y11: -0.0049748817 | Z11: 0.0046925673 | AA11: -0.00062027118 | AB11: 0.0045228131
A12: 2016-09-30 | B12: 2016-11-14 | C12: 2017-02-14 | D12: 1.0075291 | E12: 22 | F12: 0.98209019 | G12: 0.059411873 | H12: 0.03635946 | I12: 0.014920314 | J12: -0.0050807696 | K12: 0.011503259 | L12: 0.0017096093 | M12: 0.058967899 | N12: 0.036087752 | O12: 0.014808817 | P12: -0.0050428019 | Q12: 0.011417297 | R12: 0.095001962 | S12: 0.078966708 | T12: 0.010499769 | U12: -0.0013898253 | V12: 0.0055203668 | W12: 0.0014049436 | X12: 0.094292029 | Y12: 0.078376603 | Z12: 0.010421306 | AA12: -0.0013794393 | AB12: 0.0054791141
A13: 2016-12-31 | B13: 2017-02-14 | C13: 2017-05-15 | D13: 0.98562628 | E13: 22 | F13: 0.98405218 | G13: 0.075249453 | H13: 0.057990663 | I13: 0.0094071183 | J13: -0.0037969137 | K13: 0.010682279 | L13: 0.00096630629 | M13: 0.076346841 | N13: 0.05883636 | O13: 0.0095443055 | P13: -0.0038522853 | Q13: 0.010838062 | R13: 0.0073445918 | S13: 0.031688408 | T13: 0.0050126523 | U13: -0.0055304533 | V13: -0.022007486 | W13: -0.0018185301 | X13: 0.0074517004 | Y13: 0.032150531 | Z13: 0.0050857535 | AA13: -0.0056111058 | AB13: -0.022328428
... A43: 2025-09-30 | B43: 2025-11-14 | C43: 2026-02-17 | D43: 1.0403833 | E43: 22 | F43: 1 | G43: 0.080209442 | H43: 0.030160083 | I43: -0.00016856397 | J43: 0.0034829933 | K43: 0.043836017 | L43: 0.002898912 | M43: 0.070481696 | N43: 0.022649081 | O43: -0.0013857573 | P43: 0.003644229 | Q43: 0.043139369 | R43: -0.01263262 | S43: 0.016454051 | T43: 0.021518249 | U43: -0.0048635641 | V43: -0.044938086 | W43: -0.00080326999 | X43: -0.012142275 | Y43: 0.015815374 | Z43: 0.020683001 | AA43: -0.004674781 | AB43: -0.043193779

Sheet Berkshire_summary
A1: layer | B1: basis | C1: n | D1: mean_bps | E1: std_bps | F1: t | G1: hit_% | H1: skew | I1: ann_Sharpe | J1: ann_% | K1: cum_%
A2: market | B2: unlagged_fwdQ | C2: =COUNT(Berkshire_quarterly!H2:H43) | D2: =AVERAGE(Berkshire_quarterly!H2:H43)*10000 | E2: =STDEV(Berkshire_quarterly!H2:H43)*10000 | F2: =AVERAGE(Berkshire_quarterly!H2:H43)/(STDEV(Berkshire_quarterly!H2:H43)/SQRT(COUNT(Berkshire_quarterly!H2:H43))) | G2: =COUNTIF(Berkshire_quarterly!H2:H43,">0")/COUNT(Berkshire_quarterly!H2:H43)*100 | H2: =SKEW(Berkshire_quarterly!H2:H43) | I2: =AVERAGE(Berkshire_quarterly!H2:H43)/STDEV(Berkshire_quarterly!H2:H43)*SQRT(4) | J2: =(EXP((4/COUNT(Berkshire_quarterly!H2:H43))*SUMPRODUCT(LN(1+Berkshire_quarterly!H2:H43)))-1)*100 | K2: =(EXP(SUMPRODUCT(LN(1+Berkshire_quarterly!H2:H43)))-1)*100
A3: market | B3: unlagged_lagtwin | C3: =COUNT(Berkshire_quarterly!N2:N43) | D3: =AVERAGE(Berkshire_quarterly!N2:N43)*10000 | E3: =STDEV(Berkshire_quarterly!N2:N43)*10000 | F3: =AVERAGE(Berkshire_quarterly!N2:N43)/(STDEV(Berkshire_quarterly!N2:N43)/SQRT(COUNT(Berkshire_quarterly!N2:N43))) | G3: =COUNTIF(Berkshire_quarterly!N2:N43,">0")/COUNT(Berkshire_quarterly!N2:N43)*100 | H3: =SKEW(Berkshire_quarterly!N2:N43) | I3: =AVERAGE(Berkshire_quarterly!N2:N43)/STDEV(Berkshire_quarterly!N2:N43)*SQRT(4) | J3: =(EXP((4/COUNT(Berkshire_quarterly!N2:N43))*SUMPRODUCT(LN(1+Berkshire_quarterly!N2:N43)))-1)*100 | K3: =(EXP(SUMPRODUCT(LN(1+Berkshire_quarterly!N2:N43)))-1)*100
A4: market | B4: lagged_perQ | C4: =COUNT(Berkshire_quarterly!Y2:Y43) | D4: =AVERAGE(Berkshire_quarterly!Y2:Y43)*10000 | E4: =STDEV(Berkshire_quarterly!Y2:Y43)*10000 | F4: =AVERAGE(Berkshire_quarterly!Y2:Y43)/(STDEV(Berkshire_quarterly!Y2:Y43)/SQRT(COUNT(Berkshire_quarterly!Y2:Y43))) | G4: =COUNTIF(Berkshire_quarterly!Y2:Y43,">0")/COUNT(Berkshire_quarterly!Y2:Y43)*100 | H4: =SKEW(Berkshire_quarterly!Y2:Y43) | I4: =AVERAGE(Berkshire_quarterly!Y2:Y43)/STDEV(Berkshire_quarterly!Y2:Y43)*SQRT(4) | J4: =(EXP((4/COUNT(Berkshire_quarterly!Y2:Y43))*SUMPRODUCT(LN(1+Berkshire_quarterly!Y2:Y43)))-1)*100 | K4: =(EXP(SUMPRODUCT(LN(1+Berkshire_quarterly!Y2:Y43)))-1)*100
A5: sector | B5: unlagged_fwdQ | C5: =COUNT(Berkshire_quarterly!I2:I43) | D5: =AVERAGE(Berkshire_quarterly!I2:I43)*10000 | E5: =STDEV(Berkshire_quarterly!I2:I43)*10000 | F5: =AVERAGE(Berkshire_quarterly!I2:I43)/(STDEV(Berkshire_quarterly!I2:I43)/SQRT(COUNT(Berkshire_quarterly!I2:I43))) | G5: =COUNTIF(Berkshire_quarterly!I2:I43,">0")/COUNT(Berkshire_quarterly!I2:I43)*100 | H5: =SKEW(Berkshire_quarterly!I2:I43) | I5: =AVERAGE(Berkshire_quarterly!I2:I43)/STDEV(Berkshire_quarterly!I2:I43)*SQRT(4) | J5: =(EXP((4/COUNT(Berkshire_quarterly!I2:I43))*SUMPRODUCT(LN(1+Berkshire_quarterly!I2:I43)))-1)*100 | K5: =(EXP(SUMPRODUCT(LN(1+Berkshire_quarterly!I2:I43)))-1)*100
A6: sector | B6: unlagged_lagtwin | C6: =COUNT(Berkshire_quarterly!O2:O43) | D6: =AVERAGE(Berkshire_quarterly!O2:O43)*10000 | E6: =STDEV(Berkshire_quarterly!O2:O43)*10000 | F6: =AVERAGE(Berkshire_quarterly!O2:O43)/(STDEV(Berkshire_quarterly!O2:O43)/SQRT(COUNT(Berkshire_quarterly!O2:O43))) | G6: =COUNTIF(Berkshire_quarterly!O2:O43,">0")/COUNT(Berkshire_quarterly!O2:O43)*100 | H6: =SKEW(Berkshire_quarterly!O2:O43) | I6: =AVERAGE(Berkshire_quarterly!O2:O43)/STDEV(Berkshire_quarterly!O2:O43)*SQRT(4) | J6: =(EXP((4/COUNT(Berkshire_quarterly!O2:O43))*SUMPRODUCT(LN(1+Berkshire_quarterly!O2:O43)))-1)*100 | K6: =(EXP(SUMPRODUCT(LN(1+Berkshire_quarterly!O2:O43)))-1)*100
A7: sector | B7: lagged_perQ | C7: =COUNT(Berkshire_quarterly!Z2:Z43) | D7: =AVERAGE(Berkshire_quarterly!Z2:Z43)*10000 | E7: =STDEV(Berkshire_quarterly!Z2:Z43)*10000 | F7: =AVERAGE(Berkshire_quarterly!Z2:Z43)/(STDEV(Berkshire_quarterly!Z2:Z43)/SQRT(COUNT(Berkshire_quarterly!Z2:Z43))) | G7: =COUNTIF(Berkshire_quarterly!Z2:Z43,">0")/COUNT(Berkshire_quarterly!Z2:Z43)*100 | H7: =SKEW(Berkshire_quarterly!Z2:Z43) | I7: =AVERAGE(Berkshire_quarterly!Z2:Z43)/STDEV(Berkshire_quarterly!Z2:Z43)*SQRT(4) | J7: =(EXP((4/COUNT(Berkshire_quarterly!Z2:Z43))*SUMPRODUCT(LN(1+Berkshire_quarterly!Z2:Z43)))-1)*100 | K7: =(EXP(SUMPRODUCT(LN(1+Berkshire_quarterly!Z2:Z43)))-1)*100
A8: subsector | B8: unlagged_fwdQ | C8: =COUNT(Berkshire_quarterly!J2:J43) | D8: =AVERAGE(Berkshire_quarterly!J2:J43)*10000 | E8: =STDEV(Berkshire_quarterly!J2:J43)*10000 | F8: =AVERAGE(Berkshire_quarterly!J2:J43)/(STDEV(Berkshire_quarterly!J2:J43)/SQRT(COUNT(Berkshire_quarterly!J2:J43))) | G8: =COUNTIF(Berkshire_quarterly!J2:J43,">0")/COUNT(Berkshire_quarterly!J2:J43)*100 | H8: =SKEW(Berkshire_quarterly!J2:J43) | I8: =AVERAGE(Berkshire_quarterly!J2:J43)/STDEV(Berkshire_quarterly!J2:J43)*SQRT(4) | J8: =(EXP((4/COUNT(Berkshire_quarterly!J2:J43))*SUMPRODUCT(LN(1+Berkshire_quarterly!J2:J43)))-1)*100 | K8: =(EXP(SUMPRODUCT(LN(1+Berkshire_quarterly!J2:J43)))-1)*100
A9: subsector | B9: unlagged_lagtwin | C9: =COUNT(Berkshire_quarterly!P2:P43) | D9: =AVERAGE(Berkshire_quarterly!P2:P43)*10000 | E9: =STDEV(Berkshire_quarterly!P2:P43)*10000 | F9: =AVERAGE(Berkshire_quarterly!P2:P43)/(STDEV(Berkshire_quarterly!P2:P43)/SQRT(COUNT(Berkshire_quarterly!P2:P43))) | G9: =COUNTIF(Berkshire_quarterly!P2:P43,">0")/COUNT(Berkshire_quarterly!P2:P43)*100 | H9: =SKEW(Berkshire_quarterly!P2:P43) | I9: =AVERAGE(Berkshire_quarterly!P2:P43)/STDEV(Berkshire_quarterly!P2:P43)*SQRT(4) | J9: =(EXP((4/COUNT(Berkshire_quarterly!P2:P43))*SUMPRODUCT(LN(1+Berkshire_quarterly!P2:P43)))-1)*100 | K9: =(EXP(SUMPRODUCT(LN(1+Berkshire_quarterly!P2:P43)))-1)*100
A10: subsector | B10: lagged_perQ | C10: =COUNT(Berkshire_quarterly!AA2:AA43) | D10: =AVERAGE(Berkshire_quarterly!AA2:AA43)*10000 | E10: =STDEV(Berkshire_quarterly!AA2:AA43)*10000 | F10: =AVERAGE(Berkshire_quarterly!AA2:AA43)/(STDEV(Berkshire_quarterly!AA2:AA43)/SQRT(COUNT(Berkshire_quarterly!AA2:AA43))) | G10: =COUNTIF(Berkshire_quarterly!AA2:AA43,">0")/COUNT(Berkshire_quarterly!AA2:AA43)*100 | H10: =SKEW(Berkshire_quarterly!AA2:AA43) | I10: =AVERAGE(Berkshire_quarterly!AA2:AA43)/STDEV(Berkshire_quarterly!AA2:AA43)*SQRT(4) | J10: =(EXP((4/COUNT(Berkshire_quarterly!AA2:AA43))*SUMPRODUCT(LN(1+Berkshire_quarterly!AA2:AA43)))-1)*100 | K10: =(EXP(SUMPRODUCT(LN(1+Berkshire_quarterly!AA2:AA43)))-1)*100
A11: sector+subsector | B11: unlagged_fwdQ | C11: =COUNT(Berkshire_quarterly!I2:I43) | D11: =SUMPRODUCT((Berkshire_quarterly!I2:I43+Berkshire_quarterly!J2:J43))/COUNT(Berkshire_quarterly!I2:I43)*10000 | E11: =SQRT((SUMPRODUCT((Berkshire_quarterly!I2:I43+Berkshire_quarterly!J2:J43),(Berkshire_quarterly!I2:I43+Berkshire_quarterly!J2:J43))-COUNT(Berkshire_quarterly!I2:I43)*(SUMPRODUCT((Berkshire_quarterly!I2:I43+Berkshire_quarterly!J2:J43))/COUNT(Berkshire_quarterly!I2:I43))^2)/(COUNT(Berkshire_quarterly!I2:I43)-1))*10000 | F11: =D11*SQRT(C11)/E11 | G11: =SUMPRODUCT(--((Berkshire_quarterly!I2:I43+Berkshire_quarterly!J2:J43)>0))/COUNT(Berkshire_quarterly!I2:I43)*100 | I11: =(D11/10000)/(E11/10000)*SQRT(4) | J11: =(EXP((4/COUNT(Berkshire_quarterly!I2:I43))*SUMPRODUCT(LN(1+(Berkshire_quarterly!I2:I43+Berkshire_quarterly!J2:J43))))-1)*100 | K11: =(EXP(SUMPRODUCT(LN(1+(Berkshire_quarterly!I2:I43+Berkshire_quarterly!J2:J43))))-1)*100
A12: sector+subsector | B12: unlagged_lagtwin | C12: =COUNT(Berkshire_quarterly!O2:O43) | D12: =SUMPRODUCT((Berkshire_quarterly!O2:O43+Berkshire_quarterly!P2:P43))/COUNT(Berkshire_quarterly!O2:O43)*10000 | E12: =SQRT((SUMPRODUCT((Berkshire_quarterly!O2:O43+Berkshire_quarterly!P2:P43),(Berkshire_quarterly!O2:O43+Berkshire_quarterly!P2:P43))-COUNT(Berkshire_quarterly!O2:O43)*(SUMPRODUCT((Berkshire_quarterly!O2:O43+Berkshire_quarterly!P2:P43))/COUNT(Berkshire_quarterly!O2:O43))^2)/(COUNT(Berkshire_quarterly!O2:O43)-1))*10000 | F12: =D12*SQRT(C12)/E12 | G12: =SUMPRODUCT(--((Berkshire_quarterly!O2:O43+Berkshire_quarterly!P2:P43)>0))/COUNT(Berkshire_quarterly!O2:O43)*100 | I12: =(D12/10000)/(E12/10000)*SQRT(4) | J12: =(EXP((4/COUNT(Berkshire_quarterly!O2:O43))*SUMPRODUCT(LN(1+(Berkshire_quarterly!O2:O43+Berkshire_quarterly!P2:P43))))-1)*100 | K12: =(EXP(SUMPRODUCT(LN(1+(Berkshire_quarterly!O2:O43+Berkshire_quarterly!P2:P43))))-1)*100
A13: sector+subsector | B13: lagged_perQ | C13: =COUNT(Berkshire_quarterly!Z2:Z43) | D13: =SUMPRODUCT((Berkshire_quarterly!Z2:Z43+Berkshire_quarterly!AA2:AA43))/COUNT(Berkshire_quarterly!Z2:Z43)*10000 | E13: =SQRT((SUMPRODUCT((Berkshire_quarterly!Z2:Z43+Berkshire_quarterly!AA2:AA43),(Berkshire_quarterly!Z2:Z43+Berkshire_quarterly!AA2:AA43))-COUNT(Berkshire_quarterly!Z2:Z43)*(SUMPRODUCT((Berkshire_quarterly!Z2:Z43+Berkshire_quarterly!AA2:AA43))/COUNT(Berkshire_quarterly!Z2:Z43))^2)/(COUNT(Berkshire_quarterly!Z2:Z43)-1))*10000 | F13: =D13*SQRT(C13)/E13 | G13: =SUMPRODUCT(--((Berkshire_quarterly!Z2:Z43+Berkshire_quarterly!AA2:AA43)>0))/COUNT(Berkshire_quarterly!Z2:Z43)*100 | I13: =(D13/10000)/(E13/10000)*SQRT(4) | J13: =(EXP((4/COUNT(Berkshire_quarterly!Z2:Z43))*SUMPRODUCT(LN(1+(Berkshire_quarterly!Z2:Z43+Berkshire_quarterly!AA2:AA43))))-1)*100 | K13: =(EXP(SUMPRODUCT(LN(1+(Berkshire_quarterly!Z2:Z43+Berkshire_quarterly!AA2:AA43))))-1)*100
A14: mkt+sec+subsec | B14: unlagged_fwdQ | C14: =COUNT(Berkshire_quarterly!H2:H43) | D14: =SUMPRODUCT((Berkshire_quarterly!H2:H43+Berkshire_quarterly!I2:I43+Berkshire_quarterly!J2:J43))/COUNT(Berkshire_quarterly!H2:H43)*10000 | E14: =SQRT((SUMPRODUCT((Berkshire_quarterly!H2:H43+Berkshire_quarterly!I2:I43+Berkshire_quarterly!J2:J43),(Berkshire_quarterly!H2:H43+Berkshire_quarterly!I2:I43+Berkshire_quarterly!J2:J43))-COUNT(Berkshire_quarterly!H2:H43)*(SUMPRODUCT((Berkshire_quarterly!H2:H43+Berkshire_quarterly!I2:I43+Berkshire_quarterly!J2:J43))/COUNT(Berkshire_quarterly!H2:H43))^2)/(COUNT(Berkshire_quarterly!H2:H43)-1))*10000 | F14: =D14*SQRT(C14)/E14 | G14: =SUMPRODUCT(--((Berkshire_quarterly!H2:H43+Berkshire_quarterly!I2:I43+Berkshire_quarterly!J2:J43)>0))/COUNT(Berkshire_quarterly!H2:H43)*100 | I14: =(D14/10000)/(E14/10000)*SQRT(4) | J14: =(EXP((4/COUNT(Berkshire_quarterly!H2:H43))*SUMPRODUCT(LN(1+(Berkshire_quarterly!H2:H43+Berkshire_quarterly!I2:I43+Berkshire_quarterly!J2:J43))))-1)*100 | K14: =(EXP(SUMPRODUCT(LN(1+(Berkshire_quarterly!H2:H43+Berkshire_quarterly!I2:I43+Berkshire_quarterly!J2:J43))))-1)*100
A15: mkt+sec+subsec | B15: unlagged_lagtwin | C15: =COUNT(Berkshire_quarterly!N2:N43) | D15: =SUMPRODUCT((Berkshire_quarterly!N2:N43+Berkshire_quarterly!O2:O43+Berkshire_quarterly!P2:P43))/COUNT(Berkshire_quarterly!N2:N43)*10000 | E15: =SQRT((SUMPRODUCT((Berkshire_quarterly!N2:N43+Berkshire_quarterly!O2:O43+Berkshire_quarterly!P2:P43),(Berkshire_quarterly!N2:N43+Berkshire_quarterly!O2:O43+Berkshire_quarterly!P2:P43))-COUNT(Berkshire_quarterly!N2:N43)*(SUMPRODUCT((Berkshire_quarterly!N2:N43+Berkshire_quarterly!O2:O43+Berkshire_quarterly!P2:P43))/COUNT(Berkshire_quarterly!N2:N43))^2)/(COUNT(Berkshire_quarterly!N2:N43)-1))*10000 | F15: =D15*SQRT(C15)/E15 | G15: =SUMPRODUCT(--((Berkshire_quarterly!N2:N43+Berkshire_quarterly!O2:O43+Berkshire_quarterly!P2:P43)>0))/COUNT(Berkshire_quarterly!N2:N43)*100 | I15: =(D15/10000)/(E15/10000)*SQRT(4) | J15: =(EXP((4/COUNT(Berkshire_quarterly!N2:N43))*SUMPRODUCT(LN(1+(Berkshire_quarterly!N2:N43+Berkshire_quarterly!O2:O43+Berkshire_quarterly!P2:P43))))-1)*100 | K15: =(EXP(SUMPRODUCT(LN(1+(Berkshire_quarterly!N2:N43+Berkshire_quarterly!O2:O43+Berkshire_quarterly!P2:P43))))-1)*100
A16: mkt+sec+subsec | B16: lagged_perQ | C16: =COUNT(Berkshire_quarterly!Y2:Y43) | D16: =SUMPRODUCT((Berkshire_quarterly!Y2:Y43+Berkshire_quarterly!Z2:Z43+Berkshire_quarterly!AA2:AA43))/COUNT(Berkshire_quarterly!Y2:Y43)*10000 | E16: =SQRT((SUMPRODUCT((Berkshire_quarterly!Y2:Y43+Berkshire_quarterly!Z2:Z43+Berkshire_quarterly!AA2:AA43),(Berkshire_quarterly!Y2:Y43+Berkshire_quarterly!Z2:Z43+Berkshire_quarterly!AA2:AA43))-COUNT(Berkshire_quarterly!Y2:Y43)*(SUMPRODUCT((Berkshire_quarterly!Y2:Y43+Berkshire_quarterly!Z2:Z43+Berkshire_quarterly!AA2:AA43))/COUNT(Berkshire_quarterly!Y2:Y43))^2)/(COUNT(Berkshire_quarterly!Y2:Y43)-1))*10000 | F16: =D16*SQRT(C16)/E16 | G16: =SUMPRODUCT(--((Berkshire_quarterly!Y2:Y43+Berkshire_quarterly!Z2:Z43+Berkshire_quarterly!AA2:AA43)>0))/COUNT(Berkshire_quarterly!Y2:Y43)*100 | I16: =(D16/10000)/(E16/10000)*SQRT(4) | J16: =(EXP((4/COUNT(Berkshire_quarterly!Y2:Y43))*SUMPRODUCT(LN(1+(Berkshire_quarterly!Y2:Y43+Berkshire_quarterly!Z2:Z43+Berkshire_quarterly!AA2:AA43))))-1)*100 | K16: =(EXP(SUMPRODUCT(LN(1+(Berkshire_quarterly!Y2:Y43+Berkshire_quarterly!Z2:Z43+Berkshire_quarterly!AA2:AA43))))-1)*100
A17: idio | B17: unlagged_fwdQ | C17: =COUNT(Berkshire_quarterly!K2:K43) | D17: =AVERAGE(Berkshire_quarterly!K2:K43)*10000 | E17: =STDEV(Berkshire_quarterly!K2:K43)*10000 | F17: =AVERAGE(Berkshire_quarterly!K2:K43)/(STDEV(Berkshire_quarterly!K2:K43)/SQRT(COUNT(Berkshire_quarterly!K2:K43))) | G17: =COUNTIF(Berkshire_quarterly!K2:K43,">0")/COUNT(Berkshire_quarterly!K2:K43)*100 | H17: =SKEW(Berkshire_quarterly!K2:K43) | I17: =AVERAGE(Berkshire_quarterly!K2:K43)/STDEV(Berkshire_quarterly!K2:K43)*SQRT(4) | J17: =(EXP((4/COUNT(Berkshire_quarterly!K2:K43))*SUMPRODUCT(LN(1+Berkshire_quarterly!K2:K43)))-1)*100 | K17: =(EXP(SUMPRODUCT(LN(1+Berkshire_quarterly!K2:K43)))-1)*100
A18: idio | B18: unlagged_lagtwin | C18: =COUNT(Berkshire_quarterly!Q2:Q43) | D18: =AVERAGE(Berkshire_quarterly!Q2:Q43)*10000 | E18: =STDEV(Berkshire_quarterly!Q2:Q43)*10000 | F18: =AVERAGE(Berkshire_quarterly!Q2:Q43)/(STDEV(Berkshire_quarterly!Q2:Q43)/SQRT(COUNT(Berkshire_quarterly!Q2:Q43))) | G18: =COUNTIF(Berkshire_quarterly!Q2:Q43,">0")/COUNT(Berkshire_quarterly!Q2:Q43)*100 | H18: =SKEW(Berkshire_quarterly!Q2:Q43) | I18: =AVERAGE(Berkshire_quarterly!Q2:Q43)/STDEV(Berkshire_quarterly!Q2:Q43)*SQRT(4) | J18: =(EXP((4/COUNT(Berkshire_quarterly!Q2:Q43))*SUMPRODUCT(LN(1+Berkshire_quarterly!Q2:Q43)))-1)*100 | K18: =(EXP(SUMPRODUCT(LN(1+Berkshire_quarterly!Q2:Q43)))-1)*100
A19: idio | B19: lagged_perQ | C19: =COUNT(Berkshire_quarterly!AB2:AB43) | D19: =AVERAGE(Berkshire_quarterly!AB2:AB43)*10000 | E19: =STDEV(Berkshire_quarterly!AB2:AB43)*10000 | F19: =AVERAGE(Berkshire_quarterly!AB2:AB43)/(STDEV(Berkshire_quarterly!AB2:AB43)/SQRT(COUNT(Berkshire_quarterly!AB2:AB43))) | G19: =COUNTIF(Berkshire_quarterly!AB2:AB43,">0")/COUNT(Berkshire_quarterly!AB2:AB43)*100 | H19: =SKEW(Berkshire_quarterly!AB2:AB43) | I19: =AVERAGE(Berkshire_quarterly!AB2:AB43)/STDEV(Berkshire_quarterly!AB2:AB43)*SQRT(4) | J19: =(EXP((4/COUNT(Berkshire_quarterly!AB2:AB43))*SUMPRODUCT(LN(1+Berkshire_quarterly!AB2:AB43)))-1)*100 | K19: =(EXP(SUMPRODUCT(LN(1+Berkshire_quarterly!AB2:AB43)))-1)*100
A20: gross | B20: unlagged_fwdQ | C20: =COUNT(Berkshire_quarterly!G2:G43) | D20: =AVERAGE(Berkshire_quarterly!G2:G43)*10000 | E20: =STDEV(Berkshire_quarterly!G2:G43)*10000 | F20: =AVERAGE(Berkshire_quarterly!G2:G43)/(STDEV(Berkshire_quarterly!G2:G43)/SQRT(COUNT(Berkshire_quarterly!G2:G43))) | G20: =COUNTIF(Berkshire_quarterly!G2:G43,">0")/COUNT(Berkshire_quarterly!G2:G43)*100 | H20: =SKEW(Berkshire_quarterly!G2:G43) | I20: =AVERAGE(Berkshire_quarterly!G2:G43)/STDEV(Berkshire_quarterly!G2:G43)*SQRT(4) | J20: =(EXP((4/COUNT(Berkshire_quarterly!G2:G43))*SUMPRODUCT(LN(1+Berkshire_quarterly!G2:G43)))-1)*100 | K20: =(EXP(SUMPRODUCT(LN(1+Berkshire_quarterly!G2:G43)))-1)*100
A21: gross | B21: unlagged_lagtwin | C21: =COUNT(Berkshire_quarterly!M2:M43) | D21: =AVERAGE(Berkshire_quarterly!M2:M43)*10000 | E21: =STDEV(Berkshire_quarterly!M2:M43)*10000 | F21: =AVERAGE(Berkshire_quarterly!M2:M43)/(STDEV(Berkshire_quarterly!M2:M43)/SQRT(COUNT(Berkshire_quarterly!M2:M43))) | G21: =COUNTIF(Berkshire_quarterly!M2:M43,">0")/COUNT(Berkshire_quarterly!M2:M43)*100 | H21: =SKEW(Berkshire_quarterly!M2:M43) | I21: =AVERAGE(Berkshire_quarterly!M2:M43)/STDEV(Berkshire_quarterly!M2:M43)*SQRT(4) | J21: =(EXP((4/COUNT(Berkshire_quarterly!M2:M43))*SUMPRODUCT(LN(1+Berkshire_quarterly!M2:M43)))-1)*100 | K21: =(EXP(SUMPRODUCT(LN(1+Berkshire_quarterly!M2:M43)))-1)*100
A22: gross | B22: lagged_perQ | C22: =COUNT(Berkshire_quarterly!X2:X43) | D22: =AVERAGE(Berkshire_quarterly!X2:X43)*10000 | E22: =STDEV(Berkshire_quarterly!X2:X43)*10000 | F22: =AVERAGE(Berkshire_quarterly!X2:X43)/(STDEV(Berkshire_quarterly!X2:X43)/SQRT(COUNT(Berkshire_quarterly!X2:X43))) | G22: =COUNTIF(Berkshire_quarterly!X2:X43,">0")/COUNT(Berkshire_quarterly!X2:X43)*100 | H22: =SKEW(Berkshire_quarterly!X2:X43) | I22: =AVERAGE(Berkshire_quarterly!X2:X43)/STDEV(Berkshire_quarterly!X2:X43)*SQRT(4) | J22: =(EXP((4/COUNT(Berkshire_quarterly!X2:X43))*SUMPRODUCT(LN(1+Berkshire_quarterly!X2:X43)))-1)*100 | K22: =(EXP(SUMPRODUCT(LN(1+Berkshire_quarterly!X2:X43)))-1)*100

Sheet Sharpe_bridge
A1: Step | B1: Description | C1: Sharpe | D1: Delta | E1: Cause
A2: A | B2: Endpoint drop-idio (mkt+sec+subsec), ALL 46 quarters (get_filer_portfolio layer returns) | C2: 1.003 | E2: the previously published 1.00
A3: B | B3: Endpoint drop-idio, restricted to the 42 rebuildable teos | C3: 0.911 | D3: -0.092 | E3: SAMPLE — the 4 dropped rows are not Berkshire's book (below)
A4: C | B4: Daily rebuild drop-idio, same teos, teo->teo+3mo windows | C4: 0.933 | D4: 0.021 | E4: METHOD (rebuild uses actual prices; endpoint returns a model-implied gross)
A5: D | B5: Daily rebuild drop-idio, LAGGED windows (entry = teo+45 calendar days) | C5: 1.066 | D5: 0.133 | E5: the lag itself — the edge survives it
A7: WHY THE 4 ROWS ARE DROPPED
A8: 3 stub rows | B8: 2014-09-30, 2020-09-30, 2025-03-31 — each row describes a 1-2 NAME portfolio holding 0.001%-0.8% of the AUM the neighbouring quarters report. No holdings book matches them because there is no full book behind them. They are not 'unverifiable Berkshire quarters'; they are a different, tiny portfolio.
A9: 1 terminal row | B9: 2025-12-31 — the LAST row of the portfolio series carries a forward return measured over an open-ended window (teo -> the engine's data horizon), not one quarter. Its portfolio_market_return sits 1242 bps from SPY over its own forward quarter, ~21x the filer's typical deviation.
A10: their drop-idio mean | B10: 837 bps/q vs 372 bps/q for the 42 kept — that gap is the whole A->B step | E10: =why 1.003 was inflated
A12: VERDICT | B12: Do NOT quote 1.00. It is contaminated, not merely sample-selected. On a consistent sample the endpoint gives 0.91 and the independent daily rebuild 0.93; the +0.02 gap between them is the known rebuild-rich bias, not agreement. Quote a RANGE (0.91-0.93) with the sample stated, and never a single decimal.
A13: FINDING | B13: Drop-idio beats the gross book on the same sample and SURVIVES the lag (0.93 unlagged -> 1.07 lagged). That comparison is internal to one method and is the robust part; the absolute level is not.

Sheet Hit_rate
A1: Hit rate / skew — every layer, lagged & unlagged (per-quarter normalised). CORRECTS meeting note: L1/market hit = 83% unlagged, NOT 65%. 65% was sector+subsector.
A3: basis | B3: layer | C3: n | D3: hit_% | E3: binom_p | F3: mean_win_bps | G3: mean_loss_bps | H3: win/loss | I3: skew | J3: worst_bps | K3: best_bps | L3: longest_loss_run
A4: UNLAGGED | B4: market | C4: 42 | D4: 81 | E4: 0 | F4: 603 | G4: -958 | H4: 0.63 | I4: -1.19 | J4: -2527 | K4: 2221 | L4: 3
A5: UNLAGGED | B5: sector | C5: 42 | D5: 64 | E5: 0.088 | F5: 131 | G5: -92 | H5: 1.43 | I5: 1.93 | J5: -393 | K5: 852 | L5: 2
A6: UNLAGGED | B6: subsector | C6: 42 | D6: 55 | E6: 0.644 | F6: 82 | G6: -52 | H6: 1.57 | I6: 0.74 | J6: -147 | K6: 295 | L6: 3
A7: UNLAGGED | B7: sector+subsector | C7: 42 | D7: 64 | E7: 0.088 | F7: 170 | G7: -101 | H7: 1.67 | I7: 1.96 | J7: -478 | K7: 1076 | L7: 5
A8: UNLAGGED | B8: mkt+sec+subsec | C8: 42 | D8: 81 | E8: 0 | F8: 664 | G8: -834 | H8: 0.8 | I8: -0.41 | J8: -1737 | K8: 2470 | L8: 3
A9: UNLAGGED | B9: idio | C9: 42 | D9: 52 | E9: 0.878 | F9: 320 | G9: -254 | H9: 1.26 | I9: 0.14 | J9: -614 | K9: 852 | L9: 6
A10: UNLAGGED | B10: gross | C10: 42 | D10: 71 | E10: 0.008 | F10: 922 | G10: -735 | H10: 1.26 | I10: -0.35 | J10: -1937 | K10: 2933 | L10: 2
A12: LAGGED | B12: market | C12: 42 | D12: 79 | E12: 0 | F12: 562 | G12: -638 | H12: 0.88 | I12: -0.99 | J12: -2092 | K12: 2016 | L12: 2
A13: LAGGED | B13: sector | C13: 42 | D13: 62 | E13: 0.164 | F13: 134 | G13: -118 | H13: 1.14 | I13: -0.79 | J13: -683 | K13: 589 | L13: 5
A14: LAGGED | B14: subsector | C14: 42 | D14: 57 | E14: 0.441 | F14: 71 | G14: -60 | H14: 1.18 | I14: 0.71 | J14: -249 | K14: 372 | L14: 3
A15: LAGGED | B15: sector+subsector | C15: 42 | D15: 57 | E15: 0.441 | F15: 186 | G15: -124 | H15: 1.5 | I15: 0.69 | J15: -508 | K15: 721 | L15: 3
A16: LAGGED | B16: mkt+sec+subsec | C16: 42 | D16: 81 | E16: 0 | F16: 590 | G16: -631 | H16: 0.94 | I16: -0.33 | J16: -1371 | K16: 2199 | L16: 2
... A18: LAGGED | B18: gross | C18: 42 | D18: 76 | E18: 0.001 | F18: 731 | G18: -607 | H18: 1.2 | I18: 0.62 | J18: -1770 | K18: 3562 | L18: 2
A21: READ: sector+subsector has POSITIVE skew (+1.95 unlagged / +0.74 lagged) and win/loss>1 — wins more frequent AND larger. The 'frequent small wins, rare large losses' (negative-skew) pattern belongs to the MARKET layer (skew -1.21, win/loss 0.55), not the factor premium.

Sheet Lag_distribution
A1: Lag = filing_date - teo (days). Per-filer summary (raw vs ORIGINAL-filtered), then per-teo detail.
A2: Filing dates are 63-68% EXACTLY 45 across four independent filers -> largely a report_date+45 placeholder, not observed. search metadata flags filing_date_source='placeholder_lag_75d' (a different +75 default we do NOT use). Neither portfolio nor holdings response carries the flag.
A4: filer | B4: raw_n | C4: raw_median | D4: raw_max | E4: %_exactly_45 | F4: ORIG_n | G4: ORIG_p25 | H4: ORIG_median | I4: ORIG_p75 | J4: ORIG_max
A5: Berkshire | B5: 50 | C5: 45 | D5: 228 | E5: 64 | F5: not recomputed (holdings not cached)
A6: Pershing | B6: 81 | C6: 45 | D6: 168 | E6: 63 | F6: not recomputed (holdings not cached)
A7: Appaloosa | B7: 41 | C7: 45 | D7: 48 | E7: 68 | F7: not recomputed (holdings not cached)
A8: Greenlight | B8: 73 | C8: 45 | D8: 114 | E8: 67 | F8: not recomputed (holdings not cached)
A9: DEShaw | B9: 81 | C9: 45 | D9: 319 | E9: 65 | F9: 72 | G9: 45 | H9: 45 | I9: 46 | J9: 48
A12: PER-TEO DETAIL (portfolio endpoint filing_date; is_original heuristic: lag<=90 & not a known amendment)
A13: filer | B13: teo(report_date) | C13: filing_date | D13: lag_days | E13: exact_45? | F13: is_original(heuristic)
A14: Berkshire | B14: 2013-06-30 | C14: 2013-11-14 | D14: 137 | F14: AMENDMENT?
A15: Berkshire | B15: 2013-09-30 | C15: 2013-11-14 | D15: 45 | E15: YES | F15: ORIGINAL
A16: Berkshire | B16: 2013-12-31 | C16: 2014-02-14 | D16: 45 | E16: YES | F16: ORIGINAL
A17: Berkshire | B17: 2014-03-31 | C17: 2014-05-15 | D17: 45 | E17: YES | F17: ORIGINAL
A18: Berkshire | B18: 2014-06-30 | C18: 2014-08-14 | D18: 45 | E18: YES | F18: ORIGINAL
A19: Berkshire | B19: 2014-09-30 | C19: 2015-02-17 | D19: 140 | F19: AMENDMENT?
A20: Berkshire | B20: 2014-12-31 | C20: 2015-02-17 | D20: 48 | F20: ORIGINAL
A21: Berkshire | B21: 2015-03-31 | C21: 2015-05-15 | D21: 45 | E21: YES | F21: ORIGINAL
A22: Berkshire | B22: 2015-06-30 | C22: 2015-09-04 | D22: 66 | F22: ORIGINAL
A23: Berkshire | B23: 2015-09-30 | C23: 2015-11-16 | D23: 47 | F23: ORIGINAL
A24: Berkshire | B24: 2015-12-31 | C24: 2016-02-16 | D24: 47 | F24: ORIGINAL
A25: Berkshire | B25: 2016-03-31 | C25: 2016-05-16 | D25: 46 | F25: ORIGINAL
A26: Berkshire | B26: 2016-06-30 | C26: 2016-08-15 | D26: 46 | F26: ORIGINAL
A27: Berkshire | B27: 2016-09-30 | C27: 2016-11-14 | D27: 45 | E27: YES | F27: ORIGINAL
A28: Berkshire | B28: 2016-12-31 | C28: 2017-02-14 | D28: 45 | E28: YES | F28: ORIGINAL
A29: Berkshire | B29: 2017-03-31 | C29: 2017-05-15 | D29: 45 | E29: YES | F29: ORIGINAL
A30: Berkshire | B30: 2017-06-30 | C30: 2017-08-14 | D30: 45 | E30: YES | F30: ORIGINAL
A31: Berkshire | B31: 2017-09-30 | C31: 2017-11-14 | D31: 45 | E31: YES | F31: ORIGINAL
A32: Berkshire | B32: 2017-12-31 | C32: 2018-02-14 | D32: 45 | E32: YES | F32: ORIGINAL
A33: Berkshire | B33: 2018-03-31 | C33: 2018-05-15 | D33: 45 | E33: YES | F33: ORIGINAL
A34: Berkshire | B34: 2018-06-30 | C34: 2018-08-14 | D34: 45 | E34: YES | F34: ORIGINAL
A35: Berkshire | B35: 2018-09-30 | C35: 2018-11-14 | D35: 45 | E35: YES | F35: ORIGINAL
A36: Berkshire | B36: 2018-12-31 | C36: 2019-02-14 | D36: 45 | E36: YES | F36: ORIGINAL
A37: Berkshire | B37: 2019-03-31 | C37: 2019-05-15 | D37: 45 | E37: YES | F37: ORIGINAL
A38: Berkshire | B38: 2019-06-30 | C38: 2019-08-14 | D38: 45 | E38: YES | F38: ORIGINAL
... A42: Berkshire | B42: 2020-06-30 | C42: 2020-08-14 | D42: 45 | E42: YES | F42: ORIGINAL
A43: Berkshire | B43: 2020-09-30 | C43: 2021-02-16 | D43: 139 | F43: AMENDMENT?
A44: Berkshire | B44: 2020-12-31 | C44: 2021-02-16 | D44: 47 | F44: ORIGINAL
A45: Berkshire | B45: 2021-03-31 | C45: 2021-05-17 | D45: 47 | F45: ORIGINAL
A46: Berkshire | B46: 2021-09-30 | C46: 2021-11-15 | D46: 46 | F46: ORIGINAL
...
